[2024-03-20T04:31:58.762+0000] {taskinstance.py:1979} INFO - Dependencies all met for dep_context=non-requeueable deps ti=<TaskInstance: Airflow_and_Cassandra.get_rest_api_data manual__2024-03-20T04:31:53.366300+00:00 [queued]>
[2024-03-20T04:31:58.906+0000] {taskinstance.py:1979} INFO - Dependencies all met for dep_context=requeueable deps ti=<TaskInstance: Airflow_and_Cassandra.get_rest_api_data manual__2024-03-20T04:31:53.366300+00:00 [queued]>
[2024-03-20T04:31:58.913+0000] {taskinstance.py:2193} INFO - Starting attempt 1 of 1
[2024-03-20T04:31:59.174+0000] {taskinstance.py:2217} INFO - Executing <Task(PythonOperator): get_rest_api_data> on 2024-03-20 04:31:53.366300+00:00
[2024-03-20T04:31:59.568+0000] {standard_task_runner.py:60} INFO - Started process 6839 to run task
[2024-03-20T04:31:59.632+0000] {standard_task_runner.py:87} INFO - Running: ['***', 'tasks', 'run', 'Airflow_and_Cassandra', 'get_rest_api_data', 'manual__2024-03-20T04:31:53.366300+00:00', '--job-id', '357', '--raw', '--subdir', 'DAGS_FOLDER/insert_cassandra.py', '--cfg-path', '/tmp/tmpjh8zpxzd']
[2024-03-20T04:31:59.653+0000] {standard_task_runner.py:88} INFO - Job 357: Subtask get_rest_api_data
[2024-03-20T04:31:59.944+0000] {task_command.py:423} INFO - Running <TaskInstance: Airflow_and_Cassandra.get_rest_api_data manual__2024-03-20T04:31:53.366300+00:00 [running]> on host 52dfb58d56f6
[2024-03-20T04:32:00.099+0000] {taskinstance.py:2513} INFO - Exporting env vars: AIRFLOW_CTX_DAG_OWNER='***' AIRFLOW_CTX_DAG_ID='Airflow_and_Cassandra' AIRFLOW_CTX_TASK_ID='get_rest_api_data' AIRFLOW_CTX_EXECUTION_DATE='2024-03-20T04:31:53.366300+00:00' AIRFLOW_CTX_TRY_NUMBER='1' AIRFLOW_CTX_DAG_RUN_ID='manual__2024-03-20T04:31:53.366300+00:00'
[2024-03-20T04:32:00.549+0000] {taskinstance.py:2731} ERROR - Task failed with exception
Traceback (most recent call last):
  File "/home/airflow/.local/lib/python3.8/site-packages/airflow/models/taskinstance.py", line 444, in _execute_task
    result = _execute_callable(context=context, **execute_callable_kwargs)
  File "/home/airflow/.local/lib/python3.8/site-packages/airflow/models/taskinstance.py", line 414, in _execute_callable
    return execute_callable(context=context, **execute_callable_kwargs)
  File "/home/airflow/.local/lib/python3.8/site-packages/airflow/operators/python.py", line 200, in execute
    return_value = self.execute_callable()
  File "/home/airflow/.local/lib/python3.8/site-packages/airflow/operators/python.py", line 217, in execute_callable
    return self.python_callable(*self.op_args, **self.op_kwargs)
  File "/opt/airflow/dags/insert_cassandra.py", line 24, in get_rest_api_data
    task_instance.xcom_push("json_data", response_json)
NameError: name 'task_instance' is not defined
[2024-03-20T04:32:00.594+0000] {taskinstance.py:1149} INFO - Marking task as FAILED. dag_id=Airflow_and_Cassandra, task_id=get_rest_api_data, execution_date=20240320T043153, start_date=20240320T043158, end_date=20240320T043200
[2024-03-20T04:32:00.616+0000] {standard_task_runner.py:107} ERROR - Failed to execute job 357 for task get_rest_api_data (name 'task_instance' is not defined; 6839)
[2024-03-20T04:32:00.679+0000] {local_task_job_runner.py:234} INFO - Task exited with return code 1
[2024-03-20T04:32:01.152+0000] {taskinstance.py:3312} INFO - 0 downstream tasks scheduled from follow-on schedule check
