[2024-03-19T12:45:58.746+0000] {scheduler_job_runner.py:1575} WARNING - Marking task instance <TaskInstance: my_first_dag.task_2 scheduled__2023-10-02T11:43:00+00:00 [queued]> stuck in queued as failed. If the task instance has available retries, it will be retried.
[2024-03-19T12:46:05.596+0000] {scheduler_job_runner.py:781} ERROR - Executor reports task instance <TaskInstance: my_first_dag.task_2 scheduled__2023-10-02T11:43:00+00:00 [queued]> finished (failed) although the task says it's queued. (Info: None) Was the task killed externally?
