[2024-03-19T19:27:01.489+0000] {taskinstance.py:1979} INFO - Dependencies all met for dep_context=non-requeueable deps ti=<TaskInstance: Airflow_and_Cassandra.insert_dummy_data scheduled__2024-03-19T19:26:00+00:00 [queued]>
[2024-03-19T19:27:01.495+0000] {taskinstance.py:1979} INFO - Dependencies all met for dep_context=requeueable deps ti=<TaskInstance: Airflow_and_Cassandra.insert_dummy_data scheduled__2024-03-19T19:26:00+00:00 [queued]>
[2024-03-19T19:27:01.496+0000] {taskinstance.py:2193} INFO - Starting attempt 1 of 1
[2024-03-19T19:27:01.504+0000] {taskinstance.py:2217} INFO - Executing <Task(PythonOperator): insert_dummy_data> on 2024-03-19 19:26:00+00:00
[2024-03-19T19:27:01.514+0000] {standard_task_runner.py:60} INFO - Started process 293 to run task
[2024-03-19T19:27:01.519+0000] {standard_task_runner.py:87} INFO - Running: ['***', 'tasks', 'run', 'Airflow_and_Cassandra', 'insert_dummy_data', 'scheduled__2024-03-19T19:26:00+00:00', '--job-id', '11', '--raw', '--subdir', 'DAGS_FOLDER/insert_cassandra.py', '--cfg-path', '/tmp/tmpj1r0rjqg']
[2024-03-19T19:27:01.520+0000] {standard_task_runner.py:88} INFO - Job 11: Subtask insert_dummy_data
[2024-03-19T19:27:01.565+0000] {task_command.py:423} INFO - Running <TaskInstance: Airflow_and_Cassandra.insert_dummy_data scheduled__2024-03-19T19:26:00+00:00 [running]> on host 52dfb58d56f6
[2024-03-19T19:27:01.617+0000] {taskinstance.py:2513} INFO - Exporting env vars: AIRFLOW_CTX_DAG_OWNER='***' AIRFLOW_CTX_DAG_ID='Airflow_and_Cassandra' AIRFLOW_CTX_TASK_ID='insert_dummy_data' AIRFLOW_CTX_EXECUTION_DATE='2024-03-19T19:26:00+00:00' AIRFLOW_CTX_TRY_NUMBER='1' AIRFLOW_CTX_DAG_RUN_ID='scheduled__2024-03-19T19:26:00+00:00'
[2024-03-19T19:27:01.620+0000] {insert_cassandra.py:15} WARNING - Cluster.__init__ called with contact_points specified, but no load_balancing_policy. In the next major version, this will raise an error; please specify a load-balancing policy. (contact_points = ['localhost'], lbp = None)
[2024-03-19T19:27:01.622+0000] {insert_cassandra.py:16} WARNING - [control connection] Error connecting to 127.0.0.1:9042:
Traceback (most recent call last):
  File "cassandra/cluster.py", line 3577, in cassandra.cluster.ControlConnection._reconnect_internal
  File "cassandra/cluster.py", line 3599, in cassandra.cluster.ControlConnection._try_connect
  File "cassandra/cluster.py", line 1670, in cassandra.cluster.Cluster.connection_factory
  File "cassandra/connection.py", line 846, in cassandra.connection.Connection.factory
  File "/home/airflow/.local/lib/python3.8/site-packages/cassandra/io/asyncorereactor.py", line 354, in __init__
    self._connect_socket()
  File "cassandra/connection.py", line 951, in cassandra.connection.Connection._connect_socket
ConnectionRefusedError: [Errno 111] Tried connecting to [('127.0.0.1', 9042)]. Last error: Connection refused
[2024-03-19T19:27:01.625+0000] {insert_cassandra.py:16} WARNING - [control connection] Error connecting to ::1:9042:
Traceback (most recent call last):
  File "cassandra/cluster.py", line 3577, in cassandra.cluster.ControlConnection._reconnect_internal
  File "cassandra/cluster.py", line 3599, in cassandra.cluster.ControlConnection._try_connect
  File "cassandra/cluster.py", line 1670, in cassandra.cluster.Cluster.connection_factory
  File "cassandra/connection.py", line 846, in cassandra.connection.Connection.factory
  File "/home/airflow/.local/lib/python3.8/site-packages/cassandra/io/asyncorereactor.py", line 354, in __init__
    self._connect_socket()
  File "cassandra/connection.py", line 951, in cassandra.connection.Connection._connect_socket
OSError: [Errno 99] Tried connecting to [('::1', 9042, 0, 0)]. Last error: Cannot assign requested address
[2024-03-19T19:27:01.625+0000] {insert_cassandra.py:16} ERROR - Control connection failed to connect, shutting down Cluster:
Traceback (most recent call last):
  File "cassandra/cluster.py", line 1740, in cassandra.cluster.Cluster.connect
  File "cassandra/cluster.py", line 3543, in cassandra.cluster.ControlConnection.connect
  File "cassandra/cluster.py", line 3588, in cassandra.cluster.ControlConnection._reconnect_internal
cassandra.cluster.NoHostAvailable: ('Unable to connect to any servers', {'127.0.0.1:9042': ConnectionRefusedError(111, "Tried connecting to [('127.0.0.1', 9042)]. Last error: Connection refused"), '::1:9042': OSError(99, "Tried connecting to [('::1', 9042, 0, 0)]. Last error: Cannot assign requested address")})
[2024-03-19T19:27:01.626+0000] {taskinstance.py:2731} ERROR - Task failed with exception
Traceback (most recent call last):
  File "/home/airflow/.local/lib/python3.8/site-packages/airflow/models/taskinstance.py", line 444, in _execute_task
    result = _execute_callable(context=context, **execute_callable_kwargs)
  File "/home/airflow/.local/lib/python3.8/site-packages/airflow/models/taskinstance.py", line 414, in _execute_callable
    return execute_callable(context=context, **execute_callable_kwargs)
  File "/home/airflow/.local/lib/python3.8/site-packages/airflow/operators/python.py", line 200, in execute
    return_value = self.execute_callable()
  File "/home/airflow/.local/lib/python3.8/site-packages/airflow/operators/python.py", line 217, in execute_callable
    return self.python_callable(*self.op_args, **self.op_kwargs)
  File "/opt/airflow/dags/insert_cassandra.py", line 16, in insert_dummy_data_into_cassandra_db
    session = cluster.connect('news')
  File "cassandra/cluster.py", line 1717, in cassandra.cluster.Cluster.connect
  File "cassandra/cluster.py", line 1753, in cassandra.cluster.Cluster.connect
  File "cassandra/cluster.py", line 1740, in cassandra.cluster.Cluster.connect
  File "cassandra/cluster.py", line 3543, in cassandra.cluster.ControlConnection.connect
  File "cassandra/cluster.py", line 3588, in cassandra.cluster.ControlConnection._reconnect_internal
cassandra.cluster.NoHostAvailable: ('Unable to connect to any servers', {'127.0.0.1:9042': ConnectionRefusedError(111, "Tried connecting to [('127.0.0.1', 9042)]. Last error: Connection refused"), '::1:9042': OSError(99, "Tried connecting to [('::1', 9042, 0, 0)]. Last error: Cannot assign requested address")})
[2024-03-19T19:27:01.632+0000] {taskinstance.py:1149} INFO - Marking task as FAILED. dag_id=Airflow_and_Cassandra, task_id=insert_dummy_data, execution_date=20240319T192600, start_date=20240319T192701, end_date=20240319T192701
[2024-03-19T19:27:01.639+0000] {standard_task_runner.py:107} ERROR - Failed to execute job 11 for task insert_dummy_data (('Unable to connect to any servers', {'127.0.0.1:9042': ConnectionRefusedError(111, "Tried connecting to [('127.0.0.1', 9042)]. Last error: Connection refused"), '::1:9042': OSError(99, "Tried connecting to [('::1', 9042, 0, 0)]. Last error: Cannot assign requested address")}); 293)
[2024-03-19T19:27:01.655+0000] {local_task_job_runner.py:234} INFO - Task exited with return code 1
[2024-03-19T19:27:01.670+0000] {taskinstance.py:3312} INFO - 0 downstream tasks scheduled from follow-on schedule check
